Workbook
Name Slicer_Perf_Score: #N/A
Name Slicer_Salary: #N/A

Sheet Sheet3

Sheet Employee_Data
A1: Emp ID | B1: Full Name | C1: Dept Code | D1: Hire Date | E1: Salary | F1: Perf_Score | G1: Employment Status | H1: Department Name | I1: Years of Service | J1: Performance Band | K1: Bonus percentage | L1: Eligible Bonus Amount | M1: Attrition
A2: EMP127 | B2: Emily Brown | C2: IT02 | D2: 43093 | E2: 50361 | F2: 52 | G2: ACTIVE | H2: =_xlfn.XLOOKUP(UPPER(TRIM(C2)), Lookup_Departments!$A$2:$A$6, Lookup_Departments!$B$2:$B$6, "Unknown Dept") -> Information Technology | I2: =DATEDIF(Table3[[#This Row],[Hire Date]],TODAY(),"Y") -> 8 | J2: =_xlfn.XLOOKUP(Table3[[#This Row],[Perf_Score]],Table2[Min_Score],Table2[Performance_Band],"N/A",-1) -> Developing | K2: =_xlfn.XLOOKUP(Table3[[#This Row],[Performance Band]],Table2[Performance_Band],Table2[Bonus_Percentage],"N/A",0) -> 0.02 | L2: =Table3[[#This Row],[Salary]]*Table3[[#This Row],[Bonus percentage]] -> 1007.22 | M2: {=_xlfn.IFS(Table3[[#This Row],[Employment Status]]="LEFT","YES",Table3[[#This Row],[Employment Status]]="RESIGNED","YES","TRUE","NO")} -> NO
A3: EMP046 | B3: Richard Hernandez | C3: MKT04 | D3: 44659 | E3: 112673 | F3: 68.077465 | G3: ACTIVE | H3: =_xlfn.XLOOKUP(UPPER(TRIM(C3)), Lookup_Departments!$A$2:$A$6, Lookup_Departments!$B$2:$B$6, "Unknown Dept") -> Marketing | I3: =DATEDIF(Table3[[#This Row],[Hire Date]],TODAY(),"Y") -> 4 | J3: =_xlfn.XLOOKUP(Table3[[#This Row],[Perf_Score]],Table2[Min_Score],Table2[Performance_Band],"N/A",-1) -> Developing | K3: =_xlfn.XLOOKUP(Table3[[#This Row],[Performance Band]],Table2[Performance_Band],Table2[Bonus_Percentage],"N/A",0) -> 0.02 | L3: =Table3[[#This Row],[Salary]]*Table3[[#This Row],[Bonus percentage]] -> 2253.46 | M3: {=_xlfn.IFS(Table3[[#This Row],[Employment Status]]="LEFT","YES",Table3[[#This Row],[Employment Status]]="RESIGNED","YES","TRUE","NO")} -> NO
A4: EMP134 | B4: Emily Gonzalez | C4: IT02 | D4: 42431 | E4: $114,425 | F4: 54 | G4: LEFT | H4: =_xlfn.XLOOKUP(UPPER(TRIM(C4)), Lookup_Departments!$A$2:$A$6, Lookup_Departments!$B$2:$B$6, "Unknown Dept") -> Information Technology | I4: =DATEDIF(Table3[[#This Row],[Hire Date]],TODAY(),"Y") -> 10 | J4: =_xlfn.XLOOKUP(Table3[[#This Row],[Perf_Score]],Table2[Min_Score],Table2[Performance_Band],"N/A",-1) -> Developing | K4: =_xlfn.XLOOKUP(Table3[[#This Row],[Performance Band]],Table2[Performance_Band],Table2[Bonus_Percentage],"N/A",0) -> 0.02 | L4: =Table3[[#This Row],[Salary]]*Table3[[#This Row],[Bonus percentage]] -> 2288.5 | M4: {=_xlfn.IFS(Table3[[#This Row],[Employment Status]]="LEFT","YES",Table3[[#This Row],[Employment Status]]="RESIGNED","YES","TRUE","NO")} -> YES
A5: EMP139 | B5: John Martinez | C5: FIN03 | D5: 45110 | E5: 103831 | F5: 70 | G5: ACTIVE | H5: =_xlfn.XLOOKUP(UPPER(TRIM(C5)), Lookup_Departments!$A$2:$A$6, Lookup_Departments!$B$2:$B$6, "Unknown Dept") -> Finance | I5: =DATEDIF(Table3[[#This Row],[Hire Date]],TODAY(),"Y") -> 3 | J5: =_xlfn.XLOOKUP(Table3[[#This Row],[Perf_Score]],Table2[Min_Score],Table2[Performance_Band],"N/A",-1) -> Achieving | K5: =_xlfn.XLOOKUP(Table3[[#This Row],[Performance Band]],Table2[Performance_Band],Table2[Bonus_Percentage],"N/A",0) -> 0.05 | L5: =Table3[[#This Row],[Salary]]*Table3[[#This Row],[Bonus percentage]] -> 5191.55 | M5: {=_xlfn.IFS(Table3[[#This Row],[Employment Status]]="LEFT","YES",Table3[[#This Row],[Employment Status]]="RESIGNED","YES","TRUE","NO")} -> NO
A6: EMP112 | B6: Thomas Smith | C6: IT02 | D6: 44977 | E6: 73785 | F6: 40 | G6: LEFT | H6: =_xlfn.XLOOKUP(UPPER(TRIM(C6)), Lookup_Departments!$A$2:$A$6, Lookup_Departments!$B$2:$B$6, "Unknown Dept") -> Information Technology | I6: =DATEDIF(Table3[[#This Row],[Hire Date]],TODAY(),"Y") -> 3 | J6: =_xlfn.XLOOKUP(Table3[[#This Row],[Perf_Score]],Table2[Min_Score],Table2[Performance_Band],"N/A",-1) -> Needs Improvement | K6: =_xlfn.XLOOKUP(Table3[[#This Row],[Performance Band]],Table2[Performance_Band],Table2[Bonus_Percentage],"N/A",0) -> 0 | L6: =Table3[[#This Row],[Salary]]*Table3[[#This Row],[Bonus percentage]] -> 0 | M6: {=_xlfn.IFS(Table3[[#This Row],[Employment Status]]="LEFT","YES",Table3[[#This Row],[Employment Status]]="RESIGNED","YES","TRUE","NO")} -> YES
A7: EMP030 | B7: Emily Johnson | C7: OPS06 | D7: 43892 | E7: 115882 | F7: 49 | G7: ACTIVE | H7: =_xlfn.XLOOKUP(UPPER(TRIM(C7)), Lookup_Departments!$A$2:$A$6, Lookup_Departments!$B$2:$B$6, "Unknown Dept") -> Unknown Dept | I7: =DATEDIF(Table3[[#This Row],[Hire Date]],TODAY(),"Y") -> 6 | J7: =_xlfn.XLOOKUP(Table3[[#This Row],[Perf_Score]],Table2[Min_Score],Table2[Performance_Band],"N/A",-1) -> Needs Improvement | K7: =_xlfn.XLOOKUP(Table3[[#This Row],[Performance Band]],Table2[Performance_Band],Table2[Bonus_Percentage],"N/A",0) -> 0 | L7: =Table3[[#This Row],[Salary]]*Table3[[#This Row],[Bonus percentage]] -> 0 | M7: {=_xlfn.IFS(Table3[[#This Row],[Employment Status]]="LEFT","YES",Table3[[#This Row],[Employment Status]]="RESIGNED","YES","TRUE","NO")} -> NO
A8: EMP096 | B8: John Wilson | C8: OPS06 | D8: 45272 | E8: 59980 | F8: 70 | G8: LEFT | H8: =_xlfn.XLOOKUP(UPPER(TRIM(C8)), Lookup_Departments!$A$2:$A$6, Lookup_Departments!$B$2:$B$6, "Unknown Dept") -> Unknown Dept | I8: =DATEDIF(Table3[[#This Row],[Hire Date]],TODAY(),"Y") -> 2 | J8: =_xlfn.XLOOKUP(Table3[[#This Row],[Perf_Score]],Table2[Min_Score],Table2[Performance_Band],"N/A",-1) -> Achieving | K8: =_xlfn.XLOOKUP(Table3[[#This Row],[Performance Band]],Table2[Performance_Band],Table2[Bonus_Percentage],"N/A",0) -> 0.05 | L8: =Table3[[#This Row],[Salary]]*Table3[[#This Row],[Bonus percentage]] -> 2999 | M8: {=_xlfn.IFS(Table3[[#This Row],[Employment Status]]="LEFT","YES",Table3[[#This Row],[Employment Status]]="RESIGNED","YES","TRUE","NO")} -> YES
A9: EMP098 | B9: Jessica Smith | C9: OPS06 | D9: 44174 | E9: 68728 | F9: 45 | G9: ACTIVE | H9: =_xlfn.XLOOKUP(UPPER(TRIM(C9)), Lookup_Departments!$A$2:$A$6, Lookup_Departments!$B$2:$B$6, "Unknown Dept") -> Unknown Dept | I9: =DATEDIF(Table3[[#This Row],[Hire Date]],TODAY(),"Y") -> 5 | J9: =_xlfn.XLOOKUP(Table3[[#This Row],[Perf_Score]],Table2[Min_Score],Table2[Performance_Band],"N/A",-1) -> Needs Improvement | K9: =_xlfn.XLOOKUP(Table3[[#This Row],[Performance Band]],Table2[Performance_Band],Table2[Bonus_Percentage],"N/A",0) -> 0 | L9: =Table3[[#This Row],[Salary]]*Table3[[#This Row],[Bonus percentage]] -> 0 | M9: {=_xlfn.IFS(Table3[[#This Row],[Employment Status]]="LEFT","YES",Table3[[#This Row],[Employment Status]]="RESIGNED","YES","TRUE","NO")} -> NO
A10: EMP095 | B10: N/A Rodriguez | C10: FIN03 | D10: 43107 | E10: 102139 | F10: 79 | G10: ACTIVE | H10: =_xlfn.XLOOKUP(UPPER(TRIM(C10)), Lookup_Departments!$A$2:$A$6, Lookup_Departments!$B$2:$B$6, "Unknown Dept") -> Finance | I10: =DATEDIF(Table3[[#This Row],[Hire Date]],TODAY(),"Y") -> 8 | J10: =_xlfn.XLOOKUP(Table3[[#This Row],[Perf_Score]],Table2[Min_Score],Table2[Performance_Band],"N/A",-1) -> Achieving | K10: =_xlfn.XLOOKUP(Table3[[#This Row],[Performance Band]],Table2[Performance_Band],Table2[Bonus_Percentage],"N/A",0) -> 0.05 | L10: =Table3[[#This Row],[Salary]]*Table3[[#This Row],[Bonus percentage]] -> 5106.95 | M10: {=_xlfn.IFS(Table3[[#This Row],[Employment Status]]="LEFT","YES",Table3[[#This Row],[Employment Status]]="RESIGNED","YES","TRUE","NO")} -> NO
A11: EMP140 | B11: Michael Martinez | C11: SAL05 | D11: 42676 | E11: 94998 | F11: 58 | G11: ACTIVE | H11: =_xlfn.XLOOKUP(UPPER(TRIM(C11)), Lookup_Departments!$A$2:$A$6, Lookup_Departments!$B$2:$B$6, "Unknown Dept") -> Sales | I11: =DATEDIF(Table3[[#This Row],[Hire Date]],TODAY(),"Y") -> 9 | J11: =_xlfn.XLOOKUP(Table3[[#This Row],[Perf_Score]],Table2[Min_Score],Table2[Performance_Band],"N/A",-1) -> Developing | K11: =_xlfn.XLOOKUP(Table3[[#This Row],[Performance Band]],Table2[Performance_Band],Table2[Bonus_Percentage],"N/A",0) -> 0.02 | L11: =Table3[[#This Row],[Salary]]*Table3[[#This Row],[Bonus percentage]] -> 1899.96 | M11: {=_xlfn.IFS(Table3[[#This Row],[Employment Status]]="LEFT","YES",Table3[[#This Row],[Employment Status]]="RESIGNED","YES","TRUE","NO")} -> NO
A12: EMP020 | B12: Emily Miller | C12: sal05 | D12: 43911 | E12: $118,635 | F12: 49 | G12: ACTIVE | H12: =_xlfn.XLOOKUP(UPPER(TRIM(C12)), Lookup_Departments!$A$2:$A$6, Lookup_Departments!$B$2:$B$6, "Unknown Dept") -> Sales | I12: =DATEDIF(Table3[[#This Row],[Hire Date]],TODAY(),"Y") -> 6 | J12: =_xlfn.XLOOKUP(Table3[[#This Row],[Perf_Score]],Table2[Min_Score],Table2[Performance_Band],"N/A",-1) -> Needs Improvement | K12: =_xlfn.XLOOKUP(Table3[[#This Row],[Performance Band]],Table2[Performance_Band],Table2[Bonus_Percentage],"N/A",0) -> 0 | L12: =Table3[[#This Row],[Salary]]*Table3[[#This Row],[Bonus percentage]] -> 0 | M12: {=_xlfn.IFS(Table3[[#This Row],[Employment Status]]="LEFT","YES",Table3[[#This Row],[Employment Status]]="RESIGNED","YES","TRUE","NO")} -> NO
A13: EMP057 | B13: Emily Hernandez | C13: IT02 | D13: 42425 | E13: 76918 | F13: 62 | G13: ACTIVE | H13: =_xlfn.XLOOKUP(UPPER(TRIM(C13)), Lookup_Departments!$A$2:$A$6, Lookup_Departments!$B$2:$B$6, "Unknown Dept") -> Information Technology | I13: =DATEDIF(Table3[[#This Row],[Hire Date]],TODAY(),"Y") -> 10 | J13: =_xlfn.XLOOKUP(Table3[[#This Row],[Perf_Score]],Table2[Min_Score],Table2[Performance_Band],"N/A",-1) -> Developing | K13: =_xlfn.XLOOKUP(Table3[[#This Row],[Performance Band]],Table2[Performance_Band],Table2[Bonus_Percentage],"N/A",0) -> 0.02 | L13: =Table3[[#This Row],[Salary]]*Table3[[#This Row],[Bonus percentage]] -> 1538.36 | M13: {=_xlfn.IFS(Table3[[#This Row],[Employment Status]]="LEFT","YES",Table3[[#This Row],[Employment Status]]="RESIGNED","YES","TRUE","NO")} -> NO
A14: EMP016 | B14: Jane Williams | C14: mkt04 | D14: 44364 | E14: 61408 | F14: 48 | G14: ACTIVE | H14: =_xlfn.XLOOKUP(UPPER(TRIM(C14)), Lookup_Departments!$A$2:$A$6, Lookup_Departments!$B$2:$B$6, "Unknown Dept") -> Marketing | I14: =DATEDIF(Table3[[#This Row],[Hire Date]],TODAY(),"Y") -> 5 | J14: =_xlfn.XLOOKUP(Table3[[#This Row],[Perf_Score]],Table2[Min_Score],Table2[Performance_Band],"N/A",-1) -> Needs Improvement | K14: =_xlfn.XLOOKUP(Table3[[#This Row],[Performance Band]],Table2[Performance_Band],Table2[Bonus_Percentage],"N/A",0) -> 0 | L14: =Table3[[#This Row],[Salary]]*Table3[[#This Row],[Bonus percentage]] -> 0 | M14: {=_xlfn.IFS(Table3[[#This Row],[Employment Status]]="LEFT","YES",Table3[[#This Row],[Employment Status]]="RESIGNED","YES","TRUE","NO")} -> NO
A15: EMP070 | B15: Jane Miller | C15: MKT04 | D15: 44001 | E15: 99990 | F15: 54 | G15: ACTIVE | H15: =_xlfn.XLOOKUP(UPPER(TRIM(C15)), Lookup_Departments!$A$2:$A$6, Lookup_Departments!$B$2:$B$6, "Unknown Dept") -> Marketing | I15: =DATEDIF(Table3[[#This Row],[Hire Date]],TODAY(),"Y") -> 6 | J15: =_xlfn.XLOOKUP(Table3[[#This Row],[Perf_Score]],Table2[Min_Score],Table2[Performance_Band],"N/A",-1) -> Developing | K15: =_xlfn.XLOOKUP(Table3[[#This Row],[Performance Band]],Table2[Performance_Band],Table2[Bonus_Percentage],"N/A",0) -> 0.02 | L15: =Table3[[#This Row],[Salary]]*Table3[[#This Row],[Bonus percentage]] -> 1999.8 | M15: {=_xlfn.IFS(Table3[[#This Row],[Employment Status]]="LEFT","YES",Table3[[#This Row],[Employment Status]]="RESIGNED","YES","TRUE","NO")} -> NO
A16: EMP025 | B16: Robert Jones | C16: MKT04 | D16: 43820 | E16: 80385 | F16: 68.077465 | G16: ACTIVE | H16: =_xlfn.XLOOKUP(UPPER(TRIM(C16)), Lookup_Departments!$A$2:$A$6, Lookup_Departments!$B$2:$B$6, "Unknown Dept") -> Marketing | I16: =DATEDIF(Table3[[#This Row],[Hire Date]],TODAY(),"Y") -> 6 | J16: =_xlfn.XLOOKUP(Table3[[#This Row],[Perf_Score]],Table2[Min_Score],Table2[Performance_Band],"N/A",-1) -> Developing | K16: =_xlfn.XLOOKUP(Table3[[#This Row],[Performance Band]],Table2[Performance_Band],Table2[Bonus_Percentage],"N/A",0) -> 0.02 | L16: =Table3[[#This Row],[Salary]]*Table3[[#This Row],[Bonus percentage]] -> 1607.7 | M16: {=_xlfn.IFS(Table3[[#This Row],[Employment Status]]="LEFT","YES",Table3[[#This Row],[Employment Status]]="RESIGNED","YES","TRUE","NO")} -> NO
A17: EMP031 | B17: Thomas Rodriguez | C17: SAL05 | D17: 45169 | E17: 65290 | F17: 77 | G17: ACTIVE | H17: =_xlfn.XLOOKUP(UPPER(TRIM(C17)), Lookup_Departments!$A$2:$A$6, Lookup_Departments!$B$2:$B$6, "Unknown Dept") -> Sales | I17: =DATEDIF(Table3[[#This Row],[Hire Date]],TODAY(),"Y") -> 2 | J17: =_xlfn.XLOOKUP(Table3[[#This Row],[Perf_Score]],Table2[Min_Score],Table2[Performance_Band],"N/A",-1) -> Achieving | K17: =_xlfn.XLOOKUP(Table3[[#This Row],[Performance Band]],Table2[Performance_Band],Table2[Bonus_Percentage],"N/A",0) -> 0.05 | L17: =Table3[[#This Row],[Salary]]*Table3[[#This Row],[Bonus percentage]] -> 3264.5 | M17: {=_xlfn.IFS(Table3[[#This Row],[Employment Status]]="LEFT","YES",Table3[[#This Row],[Employment Status]]="RESIGNED","YES","TRUE","NO")} -> NO
A18: EMP126 | B18: Emily Davis | C18: IT02 | D18: 42337 | E18: 105765 | F18: 42 | G18: ACTIVE | H18: =_xlfn.XLOOKUP(UPPER(TRIM(C18)), Lookup_Departments!$A$2:$A$6, Lookup_Departments!$B$2:$B$6, "Unknown Dept") -> Information Technology | I18: =DATEDIF(Table3[[#This Row],[Hire Date]],TODAY(),"Y") -> 10 | J18: =_xlfn.XLOOKUP(Table3[[#This Row],[Perf_Score]],Table2[Min_Score],Table2[Performance_Band],"N/A",-1) -> Needs Improvement | K18: =_xlfn.XLOOKUP(Table3[[#This Row],[Performance Band]],Table2[Performance_Band],Table2[Bonus_Percentage],"N/A",0) -> 0 | L18: =Table3[[#This Row],[Salary]]*Table3[[#This Row],[Bonus percentage]] -> 0 | M18: {=_xlfn.IFS(Table3[[#This Row],[Employment Status]]="LEFT","YES",Table3[[#This Row],[Employment Status]]="RESIGNED","YES","TRUE","NO")} -> NO
A19: EMP109 | B19: James Martinez | C19: SAL05 | D19: 42899 | E19: 102921 | F19: 49 | G19: ACTIVE | H19: =_xlfn.XLOOKUP(UPPER(TRIM(C19)), Lookup_Departments!$A$2:$A$6, Lookup_Departments!$B$2:$B$6, "Unknown Dept") -> Sales | I19: =DATEDIF(Table3[[#This Row],[Hire Date]],TODAY(),"Y") -> 9 | J19: =_xlfn.XLOOKUP(Table3[[#This Row],[Perf_Score]],Table2[Min_Score],Table2[Performance_Band],"N/A",-1) -> Needs Improvement | K19: =_xlfn.XLOOKUP(Table3[[#This Row],[Performance Band]],Table2[Performance_Band],Table2[Bonus_Percentage],"N/A",0) -> 0 | L19: =Table3[[#This Row],[Salary]]*Table3[[#This Row],[Bonus percentage]] -> 0 | M19: {=_xlfn.IFS(Table3[[#This Row],[Employment Status]]="LEFT","YES",Table3[[#This Row],[Employment Status]]="RESIGNED","YES","TRUE","NO")} -> NO
A20: EMP066 | B20: Ashley Lopez | C20: MKT04 | D20: 42425 | E20: 73984 | F20: 93 | G20: ACTIVE | H20: =_xlfn.XLOOKUP(UPPER(TRIM(C20)), Lookup_Departments!$A$2:$A$6, Lookup_Departments!$B$2:$B$6, "Unknown Dept") -> Marketing | I20: =DATEDIF(Table3[[#This Row],[Hire Date]],TODAY(),"Y") -> 10 | J20: =_xlfn.XLOOKUP(Table3[[#This Row],[Perf_Score]],Table2[Min_Score],Table2[Performance_Band],"N/A",-1) -> Exceeding | K20: =_xlfn.XLOOKUP(Table3[[#This Row],[Performance Band]],Table2[Performance_Band],Table2[Bonus_Percentage],"N/A",0) -> 0.08 | L20: =Table3[[#This Row],[Salary]]*Table3[[#This Row],[Bonus percentage]] -> 5918.72 | M20: {=_xlfn.IFS(Table3[[#This Row],[Employment Status]]="LEFT","YES",Table3[[#This Row],[Employment Status]]="RESIGNED","YES","TRUE","NO")} -> NO
A21: EMP120 | B21: Amanda Gonzalez | C21: IT02 | D21: 43235 | E21: 82713 | F21: 75 | G21: ACTIVE | H21: =_xlfn.XLOOKUP(UPPER(TRIM(C21)), Lookup_Departments!$A$2:$A$6, Lookup_Departments!$B$2:$B$6, "Unknown Dept") -> Information Technology | I21: =DATEDIF(Table3[[#This Row],[Hire Date]],TODAY(),"Y") -> 8 | J21: =_xlfn.XLOOKUP(Table3[[#This Row],[Perf_Score]],Table2[Min_Score],Table2[Performance_Band],"N/A",-1) -> Achieving | K21: =_xlfn.XLOOKUP(Table3[[#This Row],[Performance Band]],Table2[Performance_Band],Table2[Bonus_Percentage],"N/A",0) -> 0.05 | L21: =Table3[[#This Row],[Salary]]*Table3[[#This Row],[Bonus percentage]] -> 4135.65 | M21: {=_xlfn.IFS(Table3[[#This Row],[Employment Status]]="LEFT","YES",Table3[[#This Row],[Employment Status]]="RESIGNED","YES","TRUE","NO")} -> NO
A22: EMP019 | B22: Michael Hernandez | C22: FIN03 | D22: 42575 | E22: 118527 | F22: 50 | G22: ACTIVE | H22: =_xlfn.XLOOKUP(UPPER(TRIM(C22)), Lookup_Departments!$A$2:$A$6, Lookup_Departments!$B$2:$B$6, "Unknown Dept") -> Finance | I22: =DATEDIF(Table3[[#This Row],[Hire Date]],TODAY(),"Y") -> 9 | J22: =_xlfn.XLOOKUP(Table3[[#This Row],[Perf_Score]],Table2[Min_Score],Table2[Performance_Band],"N/A",-1) -> Developing | K22: =_xlfn.XLOOKUP(Table3[[#This Row],[Performance Band]],Table2[Performance_Band],Table2[Bonus_Percentage],"N/A",0) -> 0.02 | L22: =Table3[[#This Row],[Salary]]*Table3[[#This Row],[Bonus percentage]] -> 2370.54 | M22: {=_xlfn.IFS(Table3[[#This Row],[Employment Status]]="LEFT","YES",Table3[[#This Row],[Employment Status]]="RESIGNED","YES","TRUE","NO")} -> NO
A23: EMP013 | B23: Richard Hernandez | C23: MKT04 | D23: 43076 | E23: 107871 | F23: 88 | G23: ACTIVE | H23: =_xlfn.XLOOKUP(UPPER(TRIM(C23)), Lookup_Departments!$A$2:$A$6, Lookup_Departments!$B$2:$B$6, "Unknown Dept") -> Marketing | I23: =DATEDIF(Table3[[#This Row],[Hire Date]],TODAY(),"Y") -> 8 | J23: =_xlfn.XLOOKUP(Table3[[#This Row],[Perf_Score]],Table2[Min_Score],Table2[Performance_Band],"N/A",-1) -> Exceeding | K23: =_xlfn.XLOOKUP(Table3[[#This Row],[Performance Band]],Table2[Performance_Band],Table2[Bonus_Percentage],"N/A",0) -> 0.08 | L23: =Table3[[#This Row],[Salary]]*Table3[[#This Row],[Bonus percentage]] -> 8629.68 | M23: {=_xlfn.IFS(Table3[[#This Row],[Employment Status]]="LEFT","YES",Table3[[#This Row],[Employment Status]]="RESIGNED","YES","TRUE","NO")} -> NO
A24: EMP010 | B24: Michael Rodriguez | C24: IT02 | D24: 44353 | E24: 93956 | F24: 50 | G24: LEFT | H24: =_xlfn.XLOOKUP(UPPER(TRIM(C24)), Lookup_Departments!$A$2:$A$6, Lookup_Departments!$B$2:$B$6, "Unknown Dept") -> Information Technology | I24: =DATEDIF(Table3[[#This Row],[Hire Date]],TODAY(),"Y") -> 5 | J24: =_xlfn.XLOOKUP(Table3[[#This Row],[Perf_Score]],Table2[Min_Score],Table2[Performance_Band],"N/A",-1) -> Developing | K24: =_xlfn.XLOOKUP(Table3[[#This Row],[Performance Band]],Table2[Performance_Band],Table2[Bonus_Percentage],"N/A",0) -> 0.02 | L24: =Table3[[#This Row],[Salary]]*Table3[[#This Row],[Bonus percentage]] -> 1879.12 | M24: {=_xlfn.IFS(Table3[[#This Row],[Employment Status]]="LEFT","YES",Table3[[#This Row],[Employment Status]]="RESIGNED","YES","TRUE","NO")} -> YES
... A27: EMP052 | B27: Ashley Williams | C27: SAL05 | D27: 44728 | E27: 81205 | F27: 59 | G27: ACTIVE | H27: =_xlfn.XLOOKUP(UPPER(TRIM(C27)), Lookup_Departments!$A$2:$A$6, Lookup_Departments!$B$2:$B$6, "Unknown Dept") -> Sales | I27: =DATEDIF(Table3[[#This Row],[Hire Date]],TODAY(),"Y") -> 4 | J27: =_xlfn.XLOOKUP(Table3[[#This Row],[Perf_Score]],Table2[Min_Score],Table2[Performance_Band],"N/A",-1) -> Developing | K27: =_xlfn.XLOOKUP(Table3[[#This Row],[Performance Band]],Table2[Performance_Band],Table2[Bonus_Percentage],"N/A",0) -> 0.02 | L27: =Table3[[#This Row],[Salary]]*Table3[[#This Row],[Bonus percentage]] -> 1624.1 | M27: {=_xlfn.IFS(Table3[[#This Row],[Employment Status]]="LEFT","YES",Table3[[#This Row],[Employment Status]]="RESIGNED","YES","TRUE","NO")} -> NO
A28: EMP129 | B28: John Wilson | C28: SAL05 | D28: 45134 | E28: $77,610 | F28: 88 | G28: ACTIVE | H28: =_xlfn.XLOOKUP(UPPER(TRIM(C28)), Lookup_Departments!$A$2:$A$6, Lookup_Departments!$B$2:$B$6, "Unknown Dept") -> Sales | I28: =DATEDIF(Table3[[#This Row],[Hire Date]],TODAY(),"Y") -> 2 | J28: =_xlfn.XLOOKUP(Table3[[#This Row],[Perf_Score]],Table2[Min_Score],Table2[Performance_Band],"N/A",-1) -> Exceeding | K28: =_xlfn.XLOOKUP(Table3[[#This Row],[Performance Band]],Table2[Performance_Band],Table2[Bonus_Percentage],"N/A",0) -> 0.08 | L28: =Table3[[#This Row],[Salary]]*Table3[[#This Row],[Bonus percentage]] -> 6208.8 | M28: {=_xlfn.IFS(Table3[[#This Row],[Employment Status]]="LEFT","YES",Table3[[#This Row],[Employment Status]]="RESIGNED","YES","TRUE","NO")} -> NO
A29: EMP146 | B29: Thomas Rodriguez | C29: it02 | D29: 43732 | E29: $50,873 | F29: 90 | G29: ACTIVE | H29: =_xlfn.XLOOKUP(UPPER(TRIM(C29)), Lookup_Departments!$A$2:$A$6, Lookup_Departments!$B$2:$B$6, "Unknown Dept") -> Information Technology | I29: =DATEDIF(Table3[[#This Row],[Hire Date]],TODAY(),"Y") -> 6 | J29: =_xlfn.XLOOKUP(Table3[[#This Row],[Perf_Score]],Table2[Min_Score],Table2[Performance_Band],"N/A",-1) -> Exceeding | K29: =_xlfn.XLOOKUP(Table3[[#This Row],[Performance Band]],Table2[Performance_Band],Table2[Bonus_Percentage],"N/A",0) -> 0.08 | L29: =Table3[[#This Row],[Salary]]*Table3[[#This Row],[Bonus percentage]] -> 4069.84 | M29: {=_xlfn.IFS(Table3[[#This Row],[Employment Status]]="LEFT","YES",Table3[[#This Row],[Employment Status]]="RESIGNED","YES","TRUE","NO")} -> NO
A30: EMP099 | B30: Michael Wilson | C30: fin03 | D30: 44765 | E30: 85312 | F30: 66 | G30: ACTIVE | H30: =_xlfn.XLOOKUP(UPPER(TRIM(C30)), Lookup_Departments!$A$2:$A$6, Lookup_Departments!$B$2:$B$6, "Unknown Dept") -> Finance | I30: =DATEDIF(Table3[[#This Row],[Hire Date]],TODAY(),"Y") -> 3 | J30: =_xlfn.XLOOKUP(Table3[[#This Row],[Perf_Score]],Table2[Min_Score],Table2[Performance_Band],"N/A",-1) -> Developing | K30: =_xlfn.XLOOKUP(Table3[[#This Row],[Performance Band]],Table2[Performance_Band],Table2[Bonus_Percentage],"N/A",0) -> 0.02 | L30: =Table3[[#This Row],[Salary]]*Table3[[#This Row],[Bonus percentage]] -> 1706.24 | M30: {=_xlfn.IFS(Table3[[#This Row],[Employment Status]]="LEFT","YES",Table3[[#This Row],[Employment Status]]="RESIGNED","YES","TRUE","NO")} -> NO
A31: EMP015 | B31: John Rodriguez | C31: SAL05 | D31: 43233 | E31: 82713 | F31: 68 | G31: ACTIVE | H31: =_xlfn.XLOOKUP(UPPER(TRIM(C31)), Lookup_Departments!$A$2:$A$6, Lookup_Departments!$B$2:$B$6, "Unknown Dept") -> Sales | I31: =DATEDIF(Table3[[#This Row],[Hire Date]],TODAY(),"Y") -> 8 | J31: =_xlfn.XLOOKUP(Table3[[#This Row],[Perf_Score]],Table2[Min_Score],Table2[Performance_Band],"N/A",-1) -> Developing | K31: =_xlfn.XLOOKUP(Table3[[#This Row],[Performance Band]],Table2[Performance_Band],Table2[Bonus_Percentage],"N/A",0) -> 0.02 | L31: =Table3[[#This Row],[Salary]]*Table3[[#This Row],[Bonus percentage]] -> 1654.26 | M31: {=_xlfn.IFS(Table3[[#This Row],[Employment Status]]="LEFT","YES",Table3[[#This Row],[Employment Status]]="RESIGNED","YES","TRUE","NO")} -> NO
A32: EMP076 | B32: Thomas Hernandez | C32: OPS06 | D32: 42202 | E32: 97055 | F32: 80 | G32: ACTIVE | H32: =_xlfn.XLOOKUP(UPPER(TRIM(C32)), Lookup_Departments!$A$2:$A$6, Lookup_Departments!$B$2:$B$6, "Unknown Dept") -> Unknown Dept | I32: =DATEDIF(Table3[[#This Row],[Hire Date]],TODAY(),"Y") -> 10 | J32: =_xlfn.XLOOKUP(Table3[[#This Row],[Perf_Score]],Table2[Min_Score],Table2[Performance_Band],"N/A",-1) -> Achieving | K32: =_xlfn.XLOOKUP(Table3[[#This Row],[Performance Band]],Table2[Performance_Band],Table2[Bonus_Percentage],"N/A",0) -> 0.05 | L32: =Table3[[#This Row],[Salary]]*Table3[[#This Row],[Bonus percentage]] -> 4852.75 | M32: {=_xlfn.IFS(Table3[[#This Row],[Employment Status]]="LEFT","YES",Table3[[#This Row],[Employment Status]]="RESIGNED","YES","TRUE","NO")} -> NO
A33: EMP137 | B33: Michael Johnson | C33: IT02 | D33: 42221 | E33: 66069 | F33: 72 | G33: ACTIVE | H33: =_xlfn.XLOOKUP(UPPER(TRIM(C33)), Lookup_Departments!$A$2:$A$6, Lookup_Departments!$B$2:$B$6, "Unknown Dept") -> Information Technology | I33: =DATEDIF(Table3[[#This Row],[Hire Date]],TODAY(),"Y") -> 10 | J33: =_xlfn.XLOOKUP(Table3[[#This Row],[Perf_Score]],Table2[Min_Score],Table2[Performance_Band],"N/A",-1) -> Achieving | K33: =_xlfn.XLOOKUP(Table3[[#This Row],[Performance Band]],Table2[Performance_Band],Table2[Bonus_Percentage],"N/A",0) -> 0.05 | L33: =Table3[[#This Row],[Salary]]*Table3[[#This Row],[Bonus percentage]] -> 3303.45 | M33: {=_xlfn.IFS(Table3[[#This Row],[Employment Status]]="LEFT","YES",Table3[[#This Row],[Employment Status]]="RESIGNED","YES","TRUE","NO")} -> NO
A34: EMP056 | B34: Sarah Brown | C34: it02 | D34: 45195 | E34: 90157 | F34: 58 | G34: ACTIVE | H34: =_xlfn.XLOOKUP(UPPER(TRIM(C34)), Lookup_Departments!$A$2:$A$6, Lookup_Departments!$B$2:$B$6, "Unknown Dept") -> Information Technology | I34: =DATEDIF(Table3[[#This Row],[Hire Date]],TODAY(),"Y") -> 2 | J34: =_xlfn.XLOOKUP(Table3[[#This Row],[Perf_Score]],Table2[Min_Score],Table2[Performance_Band],"N/A",-1) -> Developing | K34: =_xlfn.XLOOKUP(Table3[[#This Row],[Performance Band]],Table2[Performance_Band],Table2[Bonus_Percentage],"N/A",0) -> 0.02 | L34: =Table3[[#This Row],[Salary]]*Table3[[#This Row],[Bonus percentage]] -> 1803.14 | M34: {=_xlfn.IFS(Table3[[#This Row],[Employment Status]]="LEFT","YES",Table3[[#This Row],[Employment Status]]="RESIGNED","YES","TRUE","NO")} -> NO
A35: EMP125 | B35: Jane Martinez | C35: HR01 | D35: 43626 | E35: 59899 | F35: 78 | G35: ACTIVE | H35: =_xlfn.XLOOKUP(UPPER(TRIM(C35)), Lookup_Departments!$A$2:$A$6, Lookup_Departments!$B$2:$B$6, "Unknown Dept") -> Human Resources | I35: =DATEDIF(Table3[[#This Row],[Hire Date]],TODAY(),"Y") -> 7 | J35: =_xlfn.XLOOKUP(Table3[[#This Row],[Perf_Score]],Table2[Min_Score],Table2[Performance_Band],"N/A",-1) -> Achieving | K35: =_xlfn.XLOOKUP(Table3[[#This Row],[Performance Band]],Table2[Performance_Band],Table2[Bonus_Percentage],"N/A",0) -> 0.05 | L35: =Table3[[#This Row],[Salary]]*Table3[[#This Row],[Bonus percentage]] -> 2994.95 | M35: {=_xlfn.IFS(Table3[[#This Row],[Employment Status]]="LEFT","YES",Table3[[#This Row],[Employment Status]]="RESIGNED","YES","TRUE","NO")} -> NO
A36: EMP085 | B36: Emily Jones | C36: FIN03 | D36: 44578 | E36: 113389 | F36: 30 | G36: ACTIVE | H36: =_xlfn.XLOOKUP(UPPER(TRIM(C36)), Lookup_Departments!$A$2:$A$6, Lookup_Departments!$B$2:$B$6, "Unknown Dept") -> Finance | I36: =DATEDIF(Table3[[#This Row],[Hire Date]],TODAY(),"Y") -> 4 | J36: =_xlfn.XLOOKUP(Table3[[#This Row],[Perf_Score]],Table2[Min_Score],Table2[Performance_Band],"N/A",-1) -> Needs Improvement | K36: =_xlfn.XLOOKUP(Table3[[#This Row],[Performance Band]],Table2[Performance_Band],Table2[Bonus_Percentage],"N/A",0) -> 0 | L36: =Table3[[#This Row],[Salary]]*Table3[[#This Row],[Bonus percentage]] -> 0 | M36: {=_xlfn.IFS(Table3[[#This Row],[Employment Status]]="LEFT","YES",Table3[[#This Row],[Employment Status]]="RESIGNED","YES","TRUE","NO")} -> NO
A37: EMP106 | B37: Emily Jones | C37: IT02 | D37: 42919 | E37: 102691 | F37: 52 | G37: ACTIVE | H37: =_xlfn.XLOOKUP(UPPER(TRIM(C37)), Lookup_Departments!$A$2:$A$6, Lookup_Departments!$B$2:$B$6, "Unknown Dept") -> Information Technology | I37: =DATEDIF(Table3[[#This Row],[Hire Date]],TODAY(),"Y") -> 9 | J37: =_xlfn.XLOOKUP(Table3[[#This Row],[Perf_Score]],Table2[Min_Score],Table2[Performance_Band],"N/A",-1) -> Developing | K37: =_xlfn.XLOOKUP(Table3[[#This Row],[Performance Band]],Table2[Performance_Band],Table2[Bonus_Percentage],"N/A",0) -> 0.02 | L37: =Table3[[#This Row],[Salary]]*Table3[[#This Row],[Bonus percentage]] -> 2053.82 | M37: {=_xlfn.IFS(Table3[[#This Row],[Employment Status]]="LEFT","YES",Table3[[#This Row],[Employment Status]]="RESIGNED","YES","TRUE","NO")} -> NO
A38: EMP043 | B38: John Wilson | C38: OPS06 | D38: 42248 | E38: 111845 | F38: 98 | G38: ACTIVE | H38: =_xlfn.XLOOKUP(UPPER(TRIM(C38)), Lookup_Departments!$A$2:$A$6, Lookup_Departments!$B$2:$B$6, "Unknown Dept") -> Unknown Dept | I38: =DATEDIF(Table3[[#This Row],[Hire Date]],TODAY(),"Y") -> 10 | J38: =_xlfn.XLOOKUP(Table3[[#This Row],[Perf_Score]],Table2[Min_Score],Table2[Performance_Band],"N/A",-1) -> Outstanding | K38: =_xlfn.XLOOKUP(Table3[[#This Row],[Performance Band]],Table2[Performance_Band],Table2[Bonus_Percentage],"N/A",0) -> 0.12 | L38: =Table3[[#This Row],[Salary]]*Table3[[#This Row],[Bonus percentage]] -> 13421.4 | M38: {=_xlfn.IFS(Table3[[#This Row],[Employment Status]]="LEFT","YES",Table3[[#This Row],[Employment Status]]="RESIGNED","YES","TRUE","NO")} -> NO
A39: EMP068 | B39: Melissa Brown | C39: SAL05 | D39: 44776 | E39: 69219 | F39: 93 | G39: ACTIVE | H39: =_xlfn.XLOOKUP(UPPER(TRIM(C39)), Lookup_Departments!$A$2:$A$6, Lookup_Departments!$B$2:$B$6, "Unknown Dept") -> Sales | I39: =DATEDIF(Table3[[#This Row],[Hire Date]],TODAY(),"Y") -> 3 | J39: =_xlfn.XLOOKUP(Table3[[#This Row],[Perf_Score]],Table2[Min_Score],Table2[Performance_Band],"N/A",-1) -> Exceeding | K39: =_xlfn.XLOOKUP(Table3[[#This Row],[Performance Band]],Table2[Performance_Band],Table2[Bonus_Percentage],"N/A",0) -> 0.08 | L39: =Table3[[#This Row],[Salary]]*Table3[[#This Row],[Bonus percentage]] -> 5537.52 | M39: {=_xlfn.IFS(Table3[[#This Row],[Employment Status]]="LEFT","YES",Table3[[#This Row],[Employment Status]]="RESIGNED","YES","TRUE","NO")} -> NO
A40: EMP128 | B40: Michael Smith | C40: FIN03 | D40: 44741 | E40: 82713 | F40: 80 | G40: LEFT | H40: =_xlfn.XLOOKUP(UPPER(TRIM(C40)), Lookup_Departments!$A$2:$A$6, Lookup_Departments!$B$2:$B$6, "Unknown Dept") -> Finance | I40: =DATEDIF(Table3[[#This Row],[Hire Date]],TODAY(),"Y") -> 4 | J40: =_xlfn.XLOOKUP(Table3[[#This Row],[Perf_Score]],Table2[Min_Score],Table2[Performance_Band],"N/A",-1) -> Achieving | K40: =_xlfn.XLOOKUP(Table3[[#This Row],[Performance Band]],Table2[Performance_Band],Table2[Bonus_Percentage],"N/A",0) -> 0.05 | L40: =Table3[[#This Row],[Salary]]*Table3[[#This Row],[Bonus percentage]] -> 4135.65 | M40: {=_xlfn.IFS(Table3[[#This Row],[Employment Status]]="LEFT","YES",Table3[[#This Row],[Employment Status]]="RESIGNED","YES","TRUE","NO")} -> YES
A41: EMP027 | B41: Sarah Miller | C41: OPS06 | D41: 43949 | E41: 57514 | F41: 68.077465 | G41: ACTIVE | H41: =_xlfn.XLOOKUP(UPPER(TRIM(C41)), Lookup_Departments!$A$2:$A$6, Lookup_Departments!$B$2:$B$6, "Unknown Dept") -> Unknown Dept | I41: =DATEDIF(Table3[[#This Row],[Hire Date]],TODAY(),"Y") -> 6 | J41: =_xlfn.XLOOKUP(Table3[[#This Row],[Perf_Score]],Table2[Min_Score],Table2[Performance_Band],"N/A",-1) -> Developing | K41: =_xlfn.XLOOKUP(Table3[[#This Row],[Performance Band]],Table2[Performance_Band],Table2[Bonus_Percentage],"N/A",0) -> 0.02 | L41: =Table3[[#This Row],[Salary]]*Table3[[#This Row],[Bonus percentage]] -> 1150.28 | M41: {=_xlfn.IFS(Table3[[#This Row],[Employment Status]]="LEFT","YES",Table3[[#This Row],[Employment Status]]="RESIGNED","YES","TRUE","NO")} -> NO
... A43: EMP079 | B43: David Hernandez | C43: SAL05 | D43: 43181 | E43: 52407 | F43: 55 | G43: ACTIVE | H43: =_xlfn.XLOOKUP(UPPER(TRIM(C43)), Lookup_Departments!$A$2:$A$6, Lookup_Departments!$B$2:$B$6, "Unknown Dept") -> Sales | I43: =DATEDIF(Table3[[#This Row],[Hire Date]],TODAY(),"Y") -> 8 | J43: =_xlfn.XLOOKUP(Table3[[#This Row],[Perf_Score]],Table2[Min_Score],Table2[Performance_Band],"N/A",-1) -> Developing | K43: =_xlfn.XLOOKUP(Table3[[#This Row],[Performance Band]],Table2[Performance_Band],Table2[Bonus_Percentage],"N/A",0) -> 0.02 | L43: =Table3[[#This Row],[Salary]]*Table3[[#This Row],[Bonus percentage]] -> 1048.14 | M43: {=_xlfn.IFS(Table3[[#This Row],[Employment Status]]="LEFT","YES",Table3[[#This Row],[Employment Status]]="RESIGNED","YES","TRUE","NO")} -> NO
...

Sheet Lookup_Departments
A1: Dept_Code | B1: Department_Name
A2: HR01 | B2: Human Resources
A3: IT02 | B3: Information Technology
A4: FIN03 | B4: Finance
A5: MKT04 | B5: Marketing
A6: SAL05 | B6: Sales
A7: OPS06 | B7: Operations

Sheet Lookup_Performance
A1: Min_Score | B1: Max_Score | C1: Performance_Band | D1: Bonus_Percentage
A2: 0 | B2: 49 | C2: Needs Improvement | D2: 0
A3: 50 | B3: 69 | C3: Developing | D3: 0.02
A4: 70 | B4: 84 | C4: Achieving | D4: 0.05
A5: 85 | B5: 94 | C5: Exceeding | D5: 0.08
A6: 95 | B6: 100 | C6: Outstanding | D6: 0.12

Sheet Analysis
A2: Headcount & Salary Analysis
A3: Row Labels | B3: Count of Emp ID | C3: Average of Salary | E3: Bonus Payout Analysis
A4: Human Resources | B4: 18 | C4: 88223.692 | E4: Row Labels | F4: Count of Eligible Bonus Amount
A5: Finance | B5: 17 | C5: 87938.5 | E5: Achieving | F5: 41
A6: Marketing | B6: 19 | C6: 86693.133 | E6: Developing | F6: 41
A7: Sales | B7: 31 | C7: 81083.353 | E7: Exceeding | F7: 22
A8: Information Technology | B8: 36 | C8: 79893.409 | E8: Needs Improvement | F8: 28
A9: Unknown Dept | B9: 29 | C9: 77933.083 | E9: Outstanding | F9: 18
A10: Grand Total | B10: 150 | C10: 82713.429 | E10: Grand Total | F10: 150
A12: Performance By Status Analysis | E12: Attrition Analysis
A13: Row Labels | B13: Count of Perf_Score | E13: Row Labels | F13: Count of Emp ID
A14: ACTIVE | B14: 29 | E14: Finance | F14: 17
A15: LEFT | B15: 11 | E15: Human Resources | F15: 18
A16: active | B16: 56 | E16: Information Technology | F16: 36
A17: Actv | B17: 31 | E17: Marketing | F17: 19
A18: Left | B18: 13 | E18: Sales | F18: 31
A19: Resigned | B19: 10 | E19: Unknown Dept | F19: 29
A20: Grand Total | B20: 150 | E20: Grand Total | F20: 150
A22: Employees Analysis
A23: Count of Emp ID
A24: 150

Sheet Dashboard

Sheet Hr Summary
A1: HR EXECUTIVE ANALYTICS SUMMARY
A3: Departmental Key Metrics (Headcount, Salary & Attrition)
A4: Department Name | B4: Total Headcount | C4: Average Salary | D4: Active Count | E4: Left Count | F4: Attrition Rate
A5: Human Resources | B5: =COUNTIF(Employee_Data!$H$2:$H$158, A5) -> 18 | C5: =AVERAGEIF(Employee_Data!$H$2:$H$158, A5, Employee_Data!$E$2:$E$158) -> 87830.071 | D5: =COUNTIFS(Employee_Data!$H$2:$H$158, A5, Employee_Data!$G$2:$G$158, "*active*") -> 15 | E5: =COUNTIFS(Employee_Data!$H$2:$H$158, A5, Employee_Data!$G$2:$G$158, "*left*") + COUNTIFS(Employee_Data!$H$2:$H$158, A5, Employee_Data!$G$2:$G$158, "*Resigned*") -> 3 | F5: =E5/B5 -> 0.16666667
A6: Information Technology | B6: =COUNTIF(Employee_Data!$H$2:$H$158, A6) -> 36 | C6: =AVERAGEIF(Employee_Data!$H$2:$H$158, A6, Employee_Data!$E$2:$E$158) -> 80415.556 | D6: =COUNTIFS(Employee_Data!$H$2:$H$158, A6, Employee_Data!$G$2:$G$158, "*active*") -> 28 | E6: =COUNTIFS(Employee_Data!$H$2:$H$158, A6, Employee_Data!$G$2:$G$158, "*left*") + COUNTIFS(Employee_Data!$H$2:$H$158, A6, Employee_Data!$G$2:$G$158, "*Resigned*") -> 8 | F6: =E6/B6 -> 0.22222222
A7: Finance | B7: =COUNTIF(Employee_Data!$H$2:$H$158, A7) -> 17 | C7: =AVERAGEIF(Employee_Data!$H$2:$H$158, A7, Employee_Data!$E$2:$E$158) -> 87016.353 | D7: =COUNTIFS(Employee_Data!$H$2:$H$158, A7, Employee_Data!$G$2:$G$158, "*active*") -> 14 | E7: =COUNTIFS(Employee_Data!$H$2:$H$158, A7, Employee_Data!$G$2:$G$158, "*left*") + COUNTIFS(Employee_Data!$H$2:$H$158, A7, Employee_Data!$G$2:$G$158, "*Resigned*") -> 3 | F7: =E7/B7 -> 0.17647059
A8: Marketing | B8: =COUNTIF(Employee_Data!$H$2:$H$158, A8) -> 19 | C8: =AVERAGEIF(Employee_Data!$H$2:$H$158, A8, Employee_Data!$E$2:$E$158) -> 86444.375 | D8: =COUNTIFS(Employee_Data!$H$2:$H$158, A8, Employee_Data!$G$2:$G$158, "*active*") -> 16 | E8: =COUNTIFS(Employee_Data!$H$2:$H$158, A8, Employee_Data!$G$2:$G$158, "*left*") + COUNTIFS(Employee_Data!$H$2:$H$158, A8, Employee_Data!$G$2:$G$158, "*Resigned*") -> 3 | F8: =E8/B8 -> 0.15789474
A9: Sales | B9: =COUNTIF(Employee_Data!$H$2:$H$158, A9) -> 31 | C9: =AVERAGEIF(Employee_Data!$H$2:$H$158, A9, Employee_Data!$E$2:$E$158) -> 81604.84 | D9: =COUNTIFS(Employee_Data!$H$2:$H$158, A9, Employee_Data!$G$2:$G$158, "*active*") -> 25 | E9: =COUNTIFS(Employee_Data!$H$2:$H$158, A9, Employee_Data!$G$2:$G$158, "*left*") + COUNTIFS(Employee_Data!$H$2:$H$158, A9, Employee_Data!$G$2:$G$158, "*Resigned*") -> 6 | F9: =E9/B9 -> 0.19354839
A10: Operations | B10: =COUNTIF(Employee_Data!$H$2:$H$158, A10) -> 0 | D10: =COUNTIFS(Employee_Data!$H$2:$H$158, A10, Employee_Data!$G$2:$G$158, "*active*") -> 0 | E10: =COUNTIFS(Employee_Data!$H$2:$H$158, A10, Employee_Data!$G$2:$G$158, "*left*") + COUNTIFS(Employee_Data!$H$2:$H$158, A10, Employee_Data!$G$2:$G$158, "*Resigned*") -> 0 | F10: 0
A11: Total / Average | B11: =SUM(B5:B10) -> 121 | C11: =AVERAGE(C5:C10) -> 84662.239 | D11: =SUM(D5:D10) -> 98 | E11: =SUM(E5:E10) -> 23 | F11: =E11/B11 -> 0.19008264
A14: Performance Analysis by Employment Status
A15: Employment Status | B15: Average Performance Score
A16: Active | B16: =AVERAGEIF(Employee_Data!$G$2:$G$158, "*active*", Employee_Data!$F$2:$F$158) -> 67.746054
A17: Left | B17: =(SUMIF(Employee_Data!$G$2:$G$158, "*left*", Employee_Data!$F$2:$F$158) + SUMIF(Employee_Data!$G$2:$G$158, "*Resigned*", Employee_Data!$F$2:$F$158)) / (COUNTIF(Employee_Data!$G$2:$G$158, "*left*") + COUNTIF(Employee_Data!$G$2:$G$158, "*Resigned*")) -> 69.208161
